Workbook

Sheet Sheet1
A1: Activity ID | B1: Activity Name | C1: Original Duration | D1: Weightage | E1: BL Start | F1: BL Finish | G1: Plan % DD | H1: SBCM Prev Actual | I1: Weekly % | J1: SBCM Actual Progress | K1: Saudi consultant Progress | L1: Justification from SBCM | M1: Comment from the Consultant
D2: =SUM(D5:D1560) -> 100
A3: KAFD00330 | 6.36 | SBC | Revised Baseline-R00 | C3: 547 | E3: 45931 | F3: 46477 | G3: =SUMPRODUCT($D$6:$D$1560,G6:G1560)/($D$2) -> 0.2342476 | H3: =SUMPRODUCT(D6:D1560,H6:H1560)/(D2) -> 0.45974264 | I3: =IFERROR(J3-H3,0) -> 0.0093895165 | J3: =SUMPRODUCT($D$6:$D$1560,J6:J1560)/($D$2) -> 0.46913216
A4: Project Milestones | C4: 547 | E4: 45931 | F4: 46477
A5: Key Milestone | C5: 547 | E5: 45931 | F5: 46477
A6: MS.COM.GEN.1000 | B6: Commencement date | C6: 0 | E6: 45931
A7: MS.COM.GEN.1005 | B7: Project Completion | C7: 0 | F7: 46477
A8: Control Milestone | C8: 229 | E8: 46231 | F8: 46460
A9: MS.COM.GEN.1015 | B9: Completion of Shop Drawings | C9: 0 | F9: 46231
A10: MS.COM.GEN.1045 | B10: Completion of Material Delivery | C10: 0 | F10: 46380
A11: MS.COM.GEN.1030 | B11: Completion of Intermediate Pump Station Construction Works | C11: 0 | F11: 46382
A12: MS.COM.GEN.1035 | B12: Completion of Collection system Construction Works | C12: 0 | F12: 46406
A13: MS.COM.GEN.1025 | B13: Completion of Mobilization Works | C13: 0 | F13: 46429
A14: MS.COM.GEN.1040 | B14: Completion of RO Plaint Construction Works | C14: 0 | F14: 46460
A15: General (Preliminaries and Mobilization) | C15: 547 | E15: 45931 | F15: 46477 | G15: =SUMPRODUCT($D$17:$D$28,G17:G28)/SUM($D$17:$D$28) -> 0.13374569 | H15: =SUMPRODUCT($D$17:$D$28,H17:H28)/SUM($D$17:$D$28) -> 0.55136826 | I15: =IFERROR(J15-H15,0) -> 0.0074335426 | J15: =SUMPRODUCT($D$17:$D$28,J17:J28)/SUM($D$17:$D$28) -> 0.5588018
A16: Mobilization Works | C16: 89 | E16: 46327 | F16: 46429
A17: MO.GEN.D01.1015 | B17: Site Offices Furnitures | C17: 12 | D17: 1.2252287 | E17: 46327 | F17: 46340 | G17: =VLOOKUP(A17,Sheet2!A:G,7,) -> 0 | H17: 0.1401 | I17: =IFERROR(J17-H17,0) -> 0 | J17: =VLOOKUP(A17,Sheet2!A:H,8,) -> 0.1401
A18: MO.GEN.D01.1005 | B18: Site Access, Routes & Directive Signage | C18: 10 | D18: 0.032128017 | E18: 46341 | F18: 46351 | G18: =VLOOKUP(A18,Sheet2!A:G,7,) -> 0 | H18: 0.4164 | I18: =IFERROR(J18-H18,0) -> 0 | J18: =VLOOKUP(A18,Sheet2!A:H,8,) -> 0.4164
A19: MO.GEN.D01.1030 | B19: Temporary Facilities and Devices for Offices | C19: 20 | D19: 1.2771556 | E19: 46341 | F19: 46363 | G19: =VLOOKUP(A19,Sheet2!A:G,7,) -> 0 | H19: 0.0697 | I19: =IFERROR(J19-H19,0) -> 0 | J19: =VLOOKUP(A19,Sheet2!A:H,8,) -> 0.0697
A20: MO.GEN.D01.1006 | B20: Waste Disposal & Enviremental Protection | C20: 15 | D20: 0.58044617 | E20: 46352 | F20: 46369 | G20: =VLOOKUP(A20,Sheet2!A:G,7,) -> 0 | H20: 0.4602 | I20: =IFERROR(J20-H20,0) -> 0 | J20: =VLOOKUP(A20,Sheet2!A:H,8,) -> 0.4602
A21: MO.GEN.D01.1011 | B21: Temporary Utilities Installation | C21: 25 | D21: 0.32663484 | E21: 46364 | F21: 46392 | G21: =VLOOKUP(A21,Sheet2!A:G,7,) -> 0 | H21: 0.12 | I21: =IFERROR(J21-H21,0) -> 0 | J21: =VLOOKUP(A21,Sheet2!A:H,8,) -> 0.12
A22: MO.GEN.D01.1007 | B22: Administrative Site Offices and Facilities | C22: 30 | D22: 1.0596891 | E22: 46370 | F22: 46404 | G22: =VLOOKUP(A22,Sheet2!A:G,7,) -> 0 | H22: 0.12 | I22: =IFERROR(J22-H22,0) -> 0 | J22: =VLOOKUP(A22,Sheet2!A:H,8,) -> 0.12
A23: MO.GEN.D01.1008 | B23: Site Laboratory | C23: 12 | D23: 0.23292812 | E23: 46405 | F23: 46418 | G23: =VLOOKUP(A23,Sheet2!A:G,7,) -> 0 | H23: 0.15 | I23: =IFERROR(J23-H23,0) -> 0 | J23: =VLOOKUP(A23,Sheet2!A:H,8,) -> 0.15
A24: MO.GEN.D01.1009 | B24: Temporary roads and Signs | C24: 10 | D24: 0.34269885 | E24: 46419 | F24: 46429 | G24: =VLOOKUP(A24,Sheet2!A:G,7,) -> 0 | H24: 0.4602 | I24: =IFERROR(J24-H24,0) -> 0 | J24: =VLOOKUP(A24,Sheet2!A:H,8,) -> 0.4602
A25: General Requirements | C25: 547 | E25: 45931 | F25: 46477
A26: GN.GEN.D01.1020 | B26: Performance Security | C26: 15 | D26: 0.60240032 | E26: 46062 | F26: 46076 | G26: =VLOOKUP(A26,Sheet2!A:G,7,) -> 0 | H26: 1 | I26: =IFERROR(J26-H26,0) -> 0 | J26: =VLOOKUP(A26,Sheet2!A:H,8,) -> 1
A27: GN.GEN.D01.1025 | B27: Advance Payment Security | C27: 20 | D27: 0.60240032 | E27: 46077 | F27: 46096 | G27: =VLOOKUP(A27,Sheet2!A:G,7,) -> 0 | H27: 1 | I27: =IFERROR(J27-H27,0) -> 0 | J27: =VLOOKUP(A27,Sheet2!A:H,8,) -> 1
A28: GN.GEN.D01.1010 | B28: Preliminaries for contractors and administrative works | C28: 547 | D28: 8.7013379 | E28: 45931 | F28: 46477 | G28: =VLOOKUP(A28,Sheet2!A:G,7,) -> 0.2303 | H28: 0.7075 | I28: =IFERROR(J28-H28,0) -> 0.0128 | J28: =VLOOKUP(A28,Sheet2!A:H,8,) -> 0.7203
A29: Engineering | C29: 301 | E29: 45931 | F29: 46231 | G29: =SUMPRODUCT($D$33:$D$278,G33:G278)/SUM($D$33:$D$278) -> 0.45051724 | H29: =SUMPRODUCT($D$33:$D$278,H33:H278)/SUM($D$33:$D$278) -> 0.95544646 | I29: =IFERROR(J29-H29,0) -> 0.0016237914 | J29: =SUMPRODUCT($D$33:$D$278,J33:J278)/SUM($D$33:$D$278) -> 0.95707026
A30: RO Plant | C30: 294 | E30: 45931 | F30: 46224
A31: RO Plant Shop Drawing Submittal | C31: 228 | E31: 45931 | F31: 46204
A32: Earthworks Shop Drawing Submittal | C32: 60 | E32: 45931 | F32: 46000
A33: EN.RO.D31.SDS.1215 | B33: RO l Submission of Excavation Works shop drawing | C33: 20 | D33: 0.042351875 | E33: 45931 | F33: 45953 | G33: =VLOOKUP(A33,Sheet2!A:G,7,) -> 1 | H33: 1 | I33: =IFERROR(J33-H33,0) -> 0 | J33: =VLOOKUP(A33,Sheet2!A:H,8,) -> 1
A34: EN.RO.D31.SDS.1220 | B34: RO l Submission of Concrete Piles shop drawing | C34: 20 | D34: 0.10857193 | E34: 45955 | F34: 45977 | G34: =VLOOKUP(A34,Sheet2!A:G,7,) -> 1 | H34: 1 | I34: =IFERROR(J34-H34,0) -> 0 | J34: =VLOOKUP(A34,Sheet2!A:H,8,) -> 1
A35: EN.RO.D31.SDS.1225 | B35: RO l Submission of Prestressed anchors shop drawing | C35: 20 | D35: 0.012393463 | E35: 45978 | F35: 46000 | G35: =VLOOKUP(A35,Sheet2!A:G,7,) -> 1 | H35: 1 | I35: =IFERROR(J35-H35,0) -> 0 | J35: =VLOOKUP(A35,Sheet2!A:H,8,) -> 1
A36: Concrete Shop Drawing Submittal | C36: 122 | E36: 46001 | F36: 46147
A37: EN.RO.D03.SDS.1000 | B37: RO l Submission of Raft Foundation shop drawing | C37: 12 | D37: 0.11607215 | E37: 46001 | F37: 46014 | G37: =VLOOKUP(A37,Sheet2!A:G,7,) -> 1 | H37: 1 | I37: =IFERROR(J37-H37,0) -> 0 | J37: =VLOOKUP(A37,Sheet2!A:H,8,) -> 1
A38: EN.RO.D03.SDS.1005 | B38: RO l Submission of Tank walls shop drawing | C38: 18 | D38: 0.41078602 | E38: 46015 | F38: 46035 | G38: =VLOOKUP(A38,Sheet2!A:G,7,) -> 1 | H38: 1 | I38: =IFERROR(J38-H38,0) -> 0 | J38: =VLOOKUP(A38,Sheet2!A:H,8,) -> 1
A39: EN.RO.D03.SDS.1050 | B39: RO l Submission of Tank slab shop drawing | C39: 8 | D39: 0.061765911 | E39: 46036 | F39: 46044 | G39: =VLOOKUP(A39,Sheet2!A:G,7,) -> 1 | H39: 1 | I39: =IFERROR(J39-H39,0) -> 0 | J39: =VLOOKUP(A39,Sheet2!A:H,8,) -> 1
A40: EN.RO.D03.SDS.1010 | B40: RO l Submission of Columns shop drawing Gf | C40: 6 | D40: 0.0041984608 | E40: 46046 | F40: 46051 | G40: =VLOOKUP(A40,Sheet2!A:G,7,) -> 1 | H40: 1 | I40: =IFERROR(J40-H40,0) -> 0 | J40: =VLOOKUP(A40,Sheet2!A:H,8,) -> 1
...

Sheet QT Segment (RC Wall)
B2: 1. Qunatity for RC WALLS
B3: Stage / Segment | C3: Hight | D3: Segment1 | E3: Chamfer | F3: Segment 2 | G3: Chamfer | H3: Segment 3 | I3: Chamfer | J3: Segment 4 | K3: Chamfer | L3: Segment 5 | M3: Chamfer | N3: Segment 6 | O3: Chamfer | P3: Segment 7 | Q3: Chamfer | R3: Segment 8 | S3: Chamfer | T3: Total
B4: Area (m2) | D4: 86.2142 | E4: =1/2*(0.6*1.2) -> 0.36 | F4: 117.4783 | G4: =1/2*(0.6*1.2) -> 0.36 | H4: 103.1957 | I4: =1/2*(0.6*1.2) -> 0.36 | J4: 53.7477 | K4: =1/2*(0.6*1.2) -> 0.36 | L4: =128.5367+13.5317+5.4 -> 147.4684 | M4: =1/2*(0.6*1.2) -> 0.36 | N4: 112.6832 | O4: =1/2*(0.6*1.2) -> 0.36 | P4: 77.8146 | Q4: =1/2*(0.6*1.2) -> 0.36 | R4: 97.5485 | S4: =1/2*(0.6*1.2) -> 0.36 | T4: =SUM(D4:R4) -> 798.6706
B5: Stage 1 (1.5m) | C5: 1.5 | D5: =$D$4*C5 -> 129.3213 | E5: =E4*96.37 -> 34.6932 | F5: =$F$4*C5 -> 176.21745 | G5: =G4*231.61 -> 83.3796 | H5: =$H$4*C5 -> 154.79355 | I5: =I4*127.86 -> 46.0296 | J5: =$J$4*C5 -> 80.62155 | K5: =K4*35.53 -> 12.7908 | L5: =$L$4*C5 -> 221.2026 | M5: =M4*206.57 -> 74.3652 | N5: =$N$4*C5 -> 169.0248 | O5: =O4*251.14 -> 90.4104 | P5: =$P$4*C5 -> 116.7219 | Q5: =Q4*178.28 -> 64.1808 | R5: =$R$4*C5 -> 146.32275 | S5: =S4*62.9 -> 22.644 | T5: =SUM(D5:S5) -> 1622.7195
B6: Stage 2 (4.3m) | C6: 4.3 | D6: =$D$4*C6 -> 370.72106 | F6: =$F$4*C6 -> 505.15669 | H6: =$H$4*C6 -> 443.74151 | J6: =$J$4*C6 -> 231.11511 | L6: =$L$4*C6 -> 634.11412 | N6: =$N$4*C6 -> 484.53776 | P6: =$P$4*C6 -> 334.60278 | R6: =$R$4*C6 -> 419.45855 | T6: =SUM(D6:S6) -> 3423.4476
B7: Stage 3 (4.3m) | C7: 4.3 | D7: =$D$4*C7 -> 370.72106 | F7: =$F$4*C7 -> 505.15669 | H7: =$H$4*C7 -> 443.74151 | J7: =$J$4*C7 -> 231.11511 | L7: =$L$4*C7 -> 634.11412 | N7: =$N$4*C7 -> 484.53776 | P7: =$P$4*C7 -> 334.60278 | R7: =$R$4*C7 -> 419.45855 | T7: =SUM(D7:S7) -> 3423.4476
B8: Stage 4 (4.7m) | C8: 4.7 | D8: =$D$4*C8 -> 405.20674 | F8: =$F$4*C8 -> 552.14801 | H8: =$H$4*C8 -> 485.01979 | J8: =$J$4*C8 -> 252.61419 | L8: =$L$4*C8 -> 693.10148 | N8: =$N$4*C8 -> 529.61104 | P8: =$P$4*C8 -> 365.72862 | R8: =$R$4*C8 -> 458.47795 | T8: =SUM(D8:S8) -> 3741.9078
B11: 2. Weightage for RC WALLS
B12: Stage / Segment | C12: Hight | D12: Segment1 | F12: Segment 2 | H12: Segment 3 | J12: Segment 4 | L12: Segment 5 | N12: Segment 6 | P12: Segment 7 | R12: Segment 8 | T12: Total Actual progress
B13: Area | D13: 86.2142 | F13: 117.4783 | H13: 103.1957 | J13: 53.7477 | L13: =128.5367+13.5317+5.4 -> 147.4684 | N13: 112.6832 | P13: 77.8146 | R13: 97.5485 | T13: =SUM(D13:R13) -> 796.1506
D14: Weightage | E14: Actual progress | F14: Weightage | G14: Actual progress | H14: Weightage | I14: Actual progress | J14: Weightage | K14: Actual progress | L14: Weightage | M14: Actual progress | N14: Weightage | O14: Actual progress | P14: Weightage | Q14: Actual progress | R14: Weightage | S14: Actual progress | T14: Total
B15: Stage 1 (1.5m) | C15: 1.5 | D15: =(D5+E5)/$T$5 -> 0.10107385 | E15: 1 | F15: =(F5+G5)/$T$5 -> 0.15997654 | G15: 0.5 | H15: =(H5+I5)/$T$5 -> 0.12375716 | I15: 0.15 | J15: =(J5+K5)/$T$5 -> 0.057565309 | L15: =(L5+M5)/$T$5 -> 0.18214349 | N15: =(N5+O5)/$T$5 -> 0.1598768 | P15: =(P5+Q5)/$T$5 -> 0.11148119 | R15: =(R5+S5)/$T$5 -> 0.10412567 | T15: =(E15*D15)+(G15*F15)+(I15*H15)+(K15*J15)+(M15*L15)+(O15*N15)+(Q15*P15)+(S15*R15) -> 0.19962569
B16: Stage 2 (4.3m) | C16: 4.3 | D16: =D6/$T$6 -> 0.10828881 | F16: =F6/$T$6 -> 0.14755789 | H16: =H6/$T$6 -> 0.12961832 | J16: =J6/$T$6 -> 0.067509464 | L16: =L6/$T$6 -> 0.18522676 | N16: =N6/$T$6 -> 0.14153503 | P16: =P6/$T$6 -> 0.097738543 | R16: =R6/$T$6 -> 0.12252519 | T16: =(E16*D16)+(G16*F16)+(I16*H16)+(K16*J16)+(M16*L16)+(O16*N16)+(Q16*P16)+(S16*R16) -> 0
B17: Stage 3 (4.3m) | C17: 4.3 | D17: =D7/$T$7 -> 0.10828881 | F17: =F7/$T$7 -> 0.14755789 | H17: =H7/$T$7 -> 0.12961832 | J17: =J7/$T$7 -> 0.067509464 | L17: =L7/$T$7 -> 0.18522676 | N17: =N7/$T$7 -> 0.14153503 | P17: =P7/$T$7 -> 0.097738543 | R17: =R7/$T$7 -> 0.12252519 | T17: =(E17*D17)+(G17*F17)+(I17*H17)+(K17*J17)+(M17*L17)+(O17*N17)+(Q17*P17)+(S17*R17) -> 0
B18: Stage 4 (4.7m) | C18: 4.7 | D18: =D8/$T$8 -> 0.10828881 | F18: =F8/$T$8 -> 0.14755789 | H18: =H8/$T$8 -> 0.12961832 | J18: =J8/$T$8 -> 0.067509464 | L18: =L8/$T$8 -> 0.18522676 | N18: =N8/$T$8 -> 0.14153503 | P18: =P8/$T$8 -> 0.097738543 | R18: =R8/$T$8 -> 0.12252519 | T18: =(E18*D18)+(G18*F18)+(I18*H18)+(K18*J18)+(M18*L18)+(O18*N18)+(Q18*P18)+(S18*R18) -> 0

Sheet Breakdown for Raft found
C3: Area (m^2) | D3: Volume (m^3) | F3: Steel progress | G3: Concret progress | H3: Site progreess | J3: Steel fixing Watage | K3: 0.75
A4: Part-01 | B4: Strip 1 | C4: 544.9 | D4: =1.75*C4 -> 953.575 | E4: =D4/$D$9 -> 0.31610003 | F4: 1 | G4: 1 | H4: =(F4*$K$3+K4*$G$4) -> 1 | J4: Pouring for Raft Foundation Watage | K4: 0.25
B5: Strip 7 | C5: 645.86 | D5: =1.75*C5 -> 1130.255 | E5: =D5/$D$9 -> 0.37466758 | F5: 1 | G5: 1 | H5: =(F5*$K$3+$K$4*G5) -> 1
B6: Strip 2 | C6: 212.57 | D6: =1.75*C6 -> 371.9975 | E6: =D6/$D$9 -> 0.12331324 | F6: 1 | G6: 1 | H6: =(F6*$K$3+$K$4*G6) -> 1
B7: Strip 6 | C7: 251.92 | D7: =1.75*C7 -> 440.86 | E7: =D7/$D$9 -> 0.14614043 | F7: 0.95 | H7: =(F7*$K$3+$K$4*G7) -> 0.7125
B8: Water Chamber | C8: 200 | D8: =0.6*C8 -> 120 | E8: =D8/$D$9 -> 0.039778731 | F8: 0.2
A9: Total | C9: =SUM(C4:C8) -> 1855.25 | D9: =SUM(D4:D8) -> 3016.6875 | E9: =SUM(E4:E8) -> 1 | H9: =(E4*H4)+(E5*H5)+(E6*H6)+(E7*H7) -> 0.9182059
A10: Part-02 | B10: Strip 3 | C10: 143.46 | D10: =1.75*C10 -> 251.055 | E10: =D10/$D$15 -> 0.08967427 | F10: 0.8 | G10: 0 | H10: =(F10*$K$3)+(G10*$K$4) -> 0.6
B11: Strip 4 | C11: 488.61 | D11: =1.75*C11 -> 855.0675 | E11: =D11/$D$15 -> 0.30542134 | F11: 0.7 | H11: =(F11*$K$3)+(G11*$K$4) -> 0.525
B12: Strip 5 | C12: 368.04 | D12: =1.75*C12 -> 644.07 | E12: =D12/$D$15 -> 0.23005519 | F12: 0.5 | H12: =(F12*$K$3)+(G12*$K$4) -> 0.375
B13: Strip 2 | C13: 249.81 | D13: =1.75*C13 -> 437.1675 | E13: =D13/$D$15 -> 0.15615174 | F13: 1 | G13: 1 | H13: =(F13*$K$3)+(G13*$K$4) -> 1
B14: Strip 6 | C14: 349.87 | D14: =1.75*C14 -> 612.2725 | E14: =D14/$D$15 -> 0.21869745 | F14: 0.95 | H14: =(F14*$K$3)+(G14*$K$4) -> 0.7125
A15: Total | C15: 1599.79 | D15: =SUM(D10:D14) -> 2799.6325 | E15: =SUM(E10:E14) -> 1 | H15: =(E11*H11)+(E12*H12)+(E13*H13)+(E14*H14)+(E10*H10) -> 0.61239514
B18: Area (m^2) | C18: Thikness (m) | D18: Volume (m^3)
A19: Strip 1 | B19: 544.92 | C19: 1.75 | D19: =B19*C19 -> 953.61 | E19: =D19/$D$28 -> 0.16395468
A20: Strip 2 | B20: 462.38 | C20: 1.75 | D20: =B20*C20 -> 809.165 | E20: =D20/$D$28 -> 0.13912017
A21: Strip 3 | B21: 143.46 | C21: 1.75 | D21: =B21*C21 -> 251.055 | E21: =D21/$D$28 -> 0.04316402
A22: Strip 4 | B22: 488.61 | C22: 1.75 | D22: =B22*C22 -> 855.0675 | E22: =D22/$D$28 -> 0.14701221
A23: Strip 5 | B23: 368.04 | C23: 1.75 | D23: =B23*C23 -> 644.07 | E23: =D23/$D$28 -> 0.1107353
A24: Strip 6 | B24: 601.76 | C24: 1.75 | D24: =B24*C24 -> 1053.08 | E24: =D24/$D$28 -> 0.18105661
A25: Strip 7 | B25: 645.86 | C25: 1.75 | D25: =B25*C25 -> 1130.255 | E25: =D25/$D$28 -> 0.19432535
A26: Water Chamber | B26: 200 | C26: 0.6 | D26: =B26*C26 -> 120 | E26: =D26/$D$28 -> 0.020631664
A28: Total | B28: =SUM(B19:B26) -> 3455.03 | D28: =SUM(D19:D26) -> 5816.3025 | E28: =SUM(E19:E27) -> 1

Sheet Sheet2
A1: Activity ID | B1: Activity Name | C1: Original Duration | D1: Remaining Duration | E1: Start | F1: Finish | G1: Schedule % Complete | H1: Performance % Complete | I1: Total Float
A2: KAFD00330-636-SBC-UP-261029KAFD00330 | 636 | SBC-Update-29-Oct-26 | C2: 547 | D2: 269 | E2: 01-Oct-25 A | F2: 46593 | G2: 0.2343 | H2: 0.4691 | I2: -116
A3: KAFD00330-636-SBC-UP-261029.1Project Milestones | C3: 360 | D3: 249 | E3: 01-Oct-25 A | F3: 46593 | G3: 0 | H3: 0 | I3: -116
A4: KAFD00330-636-SBC-UP-261029.1.1Key Milestone | C4: 360 | D4: 0 | E4: 01-Oct-25 A | F4: 46593 | G4: 0 | H4: 0 | I4: -116
A5: MS.COM.GEN.1000 | B5: Commencement date | C5: 0 | D5: 0 | E5: 01-Oct-25 A | G5: 1 | H5: 1
A6: MS.COM.GEN.1005 | B6: Project Completion | C6: 0 | D6: 0 | F6: 46593 | G6: 0 | H6: 0 | I6: -116
A7: KAFD00330-636-SBC-UP-261029.1.2Control Milestone | C7: 230 | D7: 230 | E7: 46344 | F7: 46574 | G7: 0 | H7: 0 | I7: -97
A8: MS.COM.GEN.1015 | B8: Completion of Shop Drawings | C8: 0 | D8: 0 | F8: 46344 | G8: 0 | H8: 0 | I8: 133
A9: MS.COM.GEN.1030 | B9: Completion of Intermediate Pump Station Construction Works | C9: 0 | D9: 0 | F9: 46413 | G9: 0 | H9: 0 | I9: 64
A10: MS.COM.GEN.1045 | B10: Completion of Material Delivery | C10: 0 | D10: 0 | F10: 46416 | G10: 0 | H10: 0 | I10: 61
A11: MS.COM.GEN.1025 | B11: Completion of Mobilization Works | C11: 0 | D11: 0 | F11: 46462 | G11: 0 | H11: 0 | I11: 15
A12: MS.COM.GEN.1035 | B12: Completion of Collection system Construction Works | C12: 0 | D12: 0 | F12: 46491 | G12: 0 | H12: 0 | I12: -14
A13: MS.COM.GEN.1040 | B13: Completion of RO Plaint Construction Works | C13: 0 | D13: 0 | F13: 46574 | G13: 0 | H13: 0 | I13: -97
A14: KAFD00330-636-SBC-UP-261029.2General (Preliminaries and Mobilization) | C14: 547 | D14: 153 | E14: 01-Oct-25 A | F14: 46477 | G14: 0.1338 | H14: 0.5588 | I14: 0
A15: KAFD00330-636-SBC-UP-261029.2.1Mobilization Works | C15: 210 | D15: 28 | E15: 11-Jun-26 A | F15: 46462 | G15: 0 | H15: 0.1773 | I15: 13
A16: MO.GEN.D01.1005 | B16: Site Access, Routes & Directive Signage | C16: 10 | D16: 6 | E16: 11-Jun-26 A | F16: 46432 | G16: 0 | H16: 0.4164 | I16: 13
A17: MO.GEN.D01.1015 | B17: Site Offices Furnitures | C17: 12 | D17: 10 | E17: 11-Jun-26 A | F17: 46436 | G17: 0 | H17: 0.1401 | I17: 13
A18: MO.GEN.D01.1030 | B18: Temporary Facilities and Devices for Offices | C18: 20 | D18: 19 | E18: 11-Jun-26 A | F18: 46448 | G18: 0 | H18: 0.0697 | I18: 13
A19: MO.GEN.D01.1006 | B19: Waste Disposal & Enviremental Protection | C19: 15 | D19: 8 | E19: 11-Jun-26 A | F19: 46434 | G19: 0 | H19: 0.4602 | I19: 13
A20: MO.GEN.D01.1007 | B20: Administrative Site Offices and Facilities | C20: 30 | D20: 28 | E20: 11-Jun-26 A | F20: 46462 | G20: 0 | H20: 0.12 | I20: 13
A21: MO.GEN.D01.1011 | B21: Temporary Utilities Installation | C21: 25 | D21: 23 | E21: 25-Jun-26 A | F21: 46453 | G21: 0 | H21: 0.12 | I21: 18
A22: MO.GEN.D01.1008 | B22: Site Laboratory | C22: 12 | D22: 10 | E22: 25-Jun-26 A | F22: 46436 | G22: 0 | H22: 0.15 | I22: 31
A23: MO.GEN.D01.1009 | B23: Temporary roads and Signs | C23: 10 | D23: 6 | E23: 25-Jun-26 A | F23: 46432 | G23: 0 | H23: 0.4602 | I23: 35
A24: KAFD00330-636-SBC-UP-261029.2.2General Requirements | C24: 547 | D24: 153 | E24: 01-Oct-25 A | F24: 46477 | G24: 0.2023 | H24: 0.7543 | I24: 0
A25: GN.GEN.D01.1010 | B25: Preliminaries for contractors and administrative works | C25: 547 | D25: 153 | E25: 01-Oct-25 A | F25: 46477 | G25: 0.2303 | H25: 0.7203 | I25: 0
A26: GN.GEN.D01.1020 | B26: Performance Security | C26: 15 | D26: 0 | E26: 16-Apr-26 A | F26: 27-May-26 A | G26: 0 | H26: 1
A27: GN.GEN.D01.1025 | B27: Advance Payment Security | C27: 20 | D27: 0 | E27: 16-Apr-26 A | F27: 27-May-26 A | G27: 0 | H27: 1
A28: KAFD00330-636-SBC-UP-261029.3Engineering | C28: 298 | D28: 19 | E28: 01-Oct-25 A | F28: 46344 | G28: 0.4505 | H28: 0.9571 | I28: 98
A29: KAFD00330-636-SBC-UP-261029.3.1RO Plant | C29: 254 | D29: 19 | E29: 01-Oct-25 A | F29: 46344 | G29: 0.5215 | H29: 0.9563 | I29: 98
A30: KAFD00330-636-SBC-UP-261029.3.1.1RO Plant Shop Drawing Submittal | C30: 213 | D30: 9 | E30: 01-Oct-25 A | F30: 46335 | G30: 0.504 | H30: 0.9875 | I30: 91
A31: KAFD00330-636-SBC-UP-261029.3.1.1.1Earthworks Shop Drawing Submittal | C31: 60 | D31: 0 | E31: 01-Oct-25 A | F31: 26-Nov-25 A | G31: 1 | H31: 1
A32: EN.RO.D31.SDS.1215 | B32: RO l Submission of Excavation Works shop drawing | C32: 20 | D32: 0 | E32: 01-Oct-25 A | F32: 20-Oct-25 A | G32: 1 | H32: 1
A33: EN.RO.D31.SDS.1220 | B33: RO l Submission of Concrete Piles shop drawing | C33: 20 | D33: 0 | E33: 05-Nov-25 A | F33: 26-Nov-25 A | G33: 1 | H33: 1
A34: EN.RO.D31.SDS.1225 | B34: RO l Submission of Prestressed anchors shop drawing | C34: 20 | D34: 0 | E34: 20-Nov-25 A | F34: 26-Nov-25 A | G34: 1 | H34: 1
A35: KAFD00330-636-SBC-UP-261029.3.1.1.2Concrete Shop Drawing Submittal | C35: 122 | D35: 0 | E35: 13-Nov-25 A | F35: 29-Apr-26 A | G35: 0.9136 | H35: 1
A36: EN.RO.D03.SDS.1000 | B36: RO l Submission of Raft Foundation shop drawing | C36: 12 | D36: 0 | E36: 13-Nov-25 A | F36: 24-Dec-25 A | G36: 1 | H36: 1
A37: EN.RO.D03.SDS.1005 | B37: RO l Submission of Tank walls shop drawing | C37: 18 | D37: 0 | E37: 04-Dec-25 A | F37: 21-Jan-26 A | G37: 1 | H37: 1
A38: EN.RO.D03.SDS.1050 | B38: RO l Submission of Tank slab shop drawing | C38: 8 | D38: 0 | E38: 01-Jan-26 A | F38: 21-Jan-26 A | G38: 1 | H38: 1
A39: EN.RO.D03.SDS.1010 | B39: RO l Submission of Columns shop drawing Gf | C39: 6 | D39: 0 | E39: 12-Feb-26 A | F39: 24-Feb-26 A | G39: 1 | H39: 1
A40: EN.RO.D03.SDS.1015 | B40: RO l Submission of Columns shop drawing 1st | C40: 6 | D40: 0 | E40: 19-Feb-26 A | F40: 25-Feb-26 A | G40: 0 | H40: 1
...
